{
    DataVersion: 3465,
    size: [7, 7, 8],
    data: [
        {pos: [0, 0, 1], state: "colossal_reactors:reactor_casing"},
        {pos: [0, 0, 2], state: "colossal_reactors:reactor_casing"},
        {pos: [0, 0, 3], state: "colossal_reactors:reactor_casing"},
        {pos: [0, 0, 4], state: "colossal_reactors:reactor_casing"},
        {pos: [0, 0, 5], state: "colossal_reactors:reactor_casing"},
        {pos: [0, 0, 6], state: "colossal_reactors:reactor_casing"},
        {pos: [0, 0, 7], state: "colossal_reactors:reactor_casing"},
        {pos: [0, 1, 1], state: "colossal_reactors:reactor_casing"},
        {pos: [0, 1, 2], state: "colossal_reactors:reactor_glass"},
        {pos: [0, 1, 3], state: "colossal_reactors:reactor_glass"},
        {pos: [0, 1, 4], state: "colossal_reactors:reactor_glass"},
        {pos: [0, 1, 5], state: "colossal_reactors:reactor_glass"},
        {pos: [0, 1, 6], state: "colossal_reactors:reactor_glass"},
        {pos: [0, 1, 7], state: "colossal_reactors:reactor_casing"},
        {pos: [0, 2, 1], state: "colossal_reactors:reactor_casing"},
        {pos: [0, 2, 2], state: "colossal_reactors:reactor_glass"},
        {pos: [0, 2, 3], state: "colossal_reactors:reactor_glass"},
        {pos: [0, 2, 4], state: "colossal_reactors:reactor_glass"},
        {pos: [0, 2, 5], state: "colossal_reactors:reactor_glass"},
        {pos: [0, 2, 6], state: "colossal_reactors:reactor_glass"},
        {pos: [0, 2, 7], state: "colossal_reactors:reactor_casing"},
        {pos: [0, 3, 1], state: "colossal_reactors:reactor_casing"},
        {pos: [0, 3, 2], state: "colossal_reactors:reactor_glass"},
        {pos: [0, 3, 3], state: "colossal_reactors:reactor_glass"},
        {pos: [0, 3, 4], state: "colossal_reactors:reactor_glass"},
        {pos: [0, 3, 5], state: "colossal_reactors:reactor_glass"},
        {pos: [0, 3, 6], state: "colossal_reactors:reactor_glass"},
        {pos: [0, 3, 7], state: "colossal_reactors:reactor_casing"},
        {pos: [0, 4, 1], state: "colossal_reactors:reactor_casing"},
        {pos: [0, 4, 2], state: "colossal_reactors:reactor_glass"},
        {pos: [0, 4, 3], state: "colossal_reactors:reactor_glass"},
        {pos: [0, 4, 4], state: "colossal_reactors:reactor_glass"},
        {pos: [0, 4, 5], state: "colossal_reactors:reactor_glass"},
        {pos: [0, 4, 6], state: "colossal_reactors:reactor_glass"},
        {pos: [0, 4, 7], state: "colossal_reactors:reactor_casing"},
        {pos: [0, 5, 1], state: "colossal_reactors:reactor_casing"},
        {pos: [0, 5, 2], state: "colossal_reactors:reactor_glass"},
        {pos: [0, 5, 3], state: "colossal_reactors:reactor_glass"},
        {pos: [0, 5, 4], state: "colossal_reactors:reactor_glass"},
        {pos: [0, 5, 5], state: "colossal_reactors:reactor_glass"},
        {pos: [0, 5, 6], state: "colossal_reactors:reactor_glass"},
        {pos: [0, 5, 7], state: "colossal_reactors:reactor_casing"},
        {pos: [0, 6, 1], state: "colossal_reactors:reactor_casing"},
        {pos: [0, 6, 2], state: "colossal_reactors:reactor_casing"},
        {pos: [0, 6, 3], state: "colossal_reactors:reactor_casing"},
        {pos: [0, 6, 4], state: "colossal_reactors:reactor_casing"},
        {pos: [0, 6, 5], state: "colossal_reactors:reactor_casing"},
        {pos: [0, 6, 6], state: "colossal_reactors:reactor_casing"},
        {pos: [0, 6, 7], state: "colossal_reactors:reactor_casing"},
        {pos: [1, 0, 1], state: "colossal_reactors:reactor_casing"},
        {pos: [1, 0, 2], state: "colossal_reactors:reactor_casing"},
        {pos: [1, 0, 3], state: "colossal_reactors:reactor_casing"},
        {pos: [1, 0, 4], state: "colossal_reactors:reactor_casing"},
        {pos: [1, 0, 5], state: "colossal_reactors:reactor_casing"},
        {pos: [1, 0, 6], state: "colossal_reactors:reactor_casing"},
        {pos: [1, 0, 7], state: "colossal_reactors:reactor_casing"},
        {pos: [1, 1, 7], state: "colossal_reactors:reactor_glass"},
        {pos: [1, 2, 1], state: "colossal_reactors:resource_port"},
        {pos: [1, 2, 7], state: "colossal_reactors:reactor_glass"},
        {pos: [1, 3, 7], state: "colossal_reactors:reactor_glass"},
        {pos: [1, 4, 7], state: "colossal_reactors:reactor_glass"},
        {pos: [1, 5, 1], state: "colossal_reactors:power_port"},
        {pos: [1, 5, 7], state: "colossal_reactors:reactor_glass"},
        {pos: [1, 6, 1], state: "colossal_reactors:reactor_casing"},
        {pos: [1, 6, 2], state: "colossal_reactors:reactor_casing"},
        {pos: [1, 6, 3], state: "colossal_reactors:reactor_casing"},
        {pos: [1, 6, 4], state: "colossal_reactors:reactor_casing"},
        {pos: [1, 6, 5], state: "colossal_reactors:reactor_casing"},
        {pos: [1, 6, 6], state: "colossal_reactors:reactor_casing"},
        {pos: [1, 6, 7], state: "colossal_reactors:reactor_casing"},
        {pos: [2, 0, 1], state: "colossal_reactors:reactor_casing"},
        {pos: [2, 0, 2], state: "colossal_reactors:reactor_casing"},
        {pos: [2, 0, 3], state: "colossal_reactors:reactor_casing"},
        {pos: [2, 0, 4], state: "colossal_reactors:reactor_casing"},
        {pos: [2, 0, 5], state: "colossal_reactors:reactor_casing"},
        {pos: [2, 0, 6], state: "colossal_reactors:reactor_casing"},
        {pos: [2, 0, 7], state: "colossal_reactors:reactor_casing"},
        {pos: [2, 1, 7], state: "colossal_reactors:reactor_glass"},
        {pos: [2, 2, 7], state: "colossal_reactors:reactor_glass"},
        {pos: [2, 3, 7], state: "colossal_reactors:reactor_glass"},
        {pos: [2, 4, 7], state: "colossal_reactors:reactor_glass"},
        {pos: [2, 5, 7], state: "colossal_reactors:reactor_glass"},
        {pos: [2, 6, 1], state: "colossal_reactors:reactor_casing"},
        {pos: [2, 6, 2], state: "colossal_reactors:reactor_casing"},
        {pos: [2, 6, 3], state: "colossal_reactors:reactor_casing"},
        {pos: [2, 6, 4], state: "colossal_reactors:reactor_casing"},
        {pos: [2, 6, 5], state: "colossal_reactors:reactor_casing"},
        {pos: [2, 6, 6], state: "colossal_reactors:reactor_casing"},
        {pos: [2, 6, 7], state: "colossal_reactors:reactor_casing"},
        {pos: [3, 0, 1], state: "colossal_reactors:reactor_casing"},
        {pos: [3, 0, 2], state: "colossal_reactors:reactor_casing"},
        {pos: [3, 0, 3], state: "colossal_reactors:reactor_casing"},
        {pos: [3, 0, 4], state: "colossal_reactors:reactor_casing"},
        {pos: [3, 0, 5], state: "colossal_reactors:reactor_casing"},
        {pos: [3, 0, 6], state: "colossal_reactors:reactor_casing"},
        {pos: [3, 0, 7], state: "colossal_reactors:reactor_casing"},
        {pos: [3, 1, 4], state: "colossal_reactors:reactor_rod{fill:0}"},
        {pos: [3, 1, 7], state: "colossal_reactors:reactor_glass"},
        {pos: [3, 2, 4], state: "colossal_reactors:reactor_rod{fill:0}"},
        {pos: [3, 2, 7], state: "colossal_reactors:reactor_glass"},
        {pos: [3, 3, 0], state: "colossal_reactors:reactor_controller{facing:north,state:off}"},
        {pos: [3, 3, 4], state: "colossal_reactors:reactor_rod{fill:0}"},
        {pos: [3, 3, 7], state: "colossal_reactors:reactor_glass"},
        {pos: [3, 4, 4], state: "colossal_reactors:reactor_rod{fill:0}"},
        {pos: [3, 4, 7], state: "colossal_reactors:reactor_glass"},
        {pos: [3, 5, 4], state: "colossal_reactors:reactor_rod{fill:0}"},
        {pos: [3, 5, 7], state: "colossal_reactors:reactor_glass"},
        {pos: [3, 6, 1], state: "colossal_reactors:reactor_casing"},
        {pos: [3, 6, 2], state: "colossal_reactors:reactor_casing"},
        {pos: [3, 6, 3], state: "colossal_reactors:reactor_casing"},
        {pos: [3, 6, 4], state: "colossal_reactors:rod_controller"},
        {pos: [3, 6, 5], state: "colossal_reactors:reactor_casing"},
        {pos: [3, 6, 6], state: "colossal_reactors:reactor_casing"},
        {pos: [3, 6, 7], state: "colossal_reactors:reactor_casing"},
        {pos: [4, 0, 1], state: "colossal_reactors:reactor_casing"},
        {pos: [4, 0, 2], state: "colossal_reactors:reactor_casing"},
        {pos: [4, 0, 3], state: "colossal_reactors:reactor_casing"},
        {pos: [4, 0, 4], state: "colossal_reactors:reactor_casing"},
        {pos: [4, 0, 5], state: "colossal_reactors:reactor_casing"},
        {pos: [4, 0, 6], state: "colossal_reactors:reactor_casing"},
        {pos: [4, 0, 7], state: "colossal_reactors:reactor_casing"},
        {pos: [4, 1, 7], state: "colossal_reactors:reactor_glass"},
        {pos: [4, 2, 7], state: "colossal_reactors:reactor_glass"},
        {pos: [4, 3, 7], state: "colossal_reactors:reactor_glass"},
        {pos: [4, 4, 7], state: "colossal_reactors:reactor_glass"},
        {pos: [4, 5, 7], state: "colossal_reactors:reactor_glass"},
        {pos: [4, 6, 1], state: "colossal_reactors:reactor_casing"},
        {pos: [4, 6, 2], state: "colossal_reactors:reactor_casing"},
        {pos: [4, 6, 3], state: "colossal_reactors:reactor_casing"},
        {pos: [4, 6, 4], state: "colossal_reactors:reactor_casing"},
        {pos: [4, 6, 5], state: "colossal_reactors:reactor_casing"},
        {pos: [4, 6, 6], state: "colossal_reactors:reactor_casing"},
        {pos: [4, 6, 7], state: "colossal_reactors:reactor_casing"},
        {pos: [5, 0, 1], state: "colossal_reactors:reactor_casing"},
        {pos: [5, 0, 2], state: "colossal_reactors:reactor_casing"},
        {pos: [5, 0, 3], state: "colossal_reactors:reactor_casing"},
        {pos: [5, 0, 4], state: "colossal_reactors:reactor_casing"},
        {pos: [5, 0, 5], state: "colossal_reactors:reactor_casing"},
        {pos: [5, 0, 6], state: "colossal_reactors:reactor_casing"},
        {pos: [5, 0, 7], state: "colossal_reactors:reactor_casing"},
        {pos: [5, 1, 7], state: "colossal_reactors:reactor_glass"},
        {pos: [5, 2, 1], state: "colossal_reactors:resource_port"},
        {pos: [5, 2, 7], state: "colossal_reactors:reactor_glass"},
        {pos: [5, 3, 7], state: "colossal_reactors:reactor_glass"},
        {pos: [5, 4, 7], state: "colossal_reactors:reactor_glass"},
        {pos: [5, 5, 7], state: "colossal_reactors:reactor_glass"},
        {pos: [5, 6, 1], state: "colossal_reactors:reactor_casing"},
        {pos: [5, 6, 2], state: "colossal_reactors:reactor_casing"},
        {pos: [5, 6, 3], state: "colossal_reactors:reactor_casing"},
        {pos: [5, 6, 4], state: "colossal_reactors:reactor_casing"},
        {pos: [5, 6, 5], state: "colossal_reactors:reactor_casing"},
        {pos: [5, 6, 6], state: "colossal_reactors:reactor_casing"},
        {pos: [5, 6, 7], state: "colossal_reactors:reactor_casing"},
        {pos: [6, 0, 1], state: "colossal_reactors:reactor_casing"},
        {pos: [6, 0, 2], state: "colossal_reactors:reactor_casing"},
        {pos: [6, 0, 3], state: "colossal_reactors:reactor_casing"},
        {pos: [6, 0, 4], state: "colossal_reactors:reactor_casing"},
        {pos: [6, 0, 5], state: "colossal_reactors:reactor_casing"},
        {pos: [6, 0, 6], state: "colossal_reactors:reactor_casing"},
        {pos: [6, 0, 7], state: "colossal_reactors:reactor_casing"},
        {pos: [6, 1, 1], state: "colossal_reactors:reactor_casing"},
        {pos: [6, 1, 2], state: "colossal_reactors:reactor_glass"},
        {pos: [6, 1, 3], state: "colossal_reactors:reactor_glass"},
        {pos: [6, 1, 4], state: "colossal_reactors:reactor_glass"},
        {pos: [6, 1, 5], state: "colossal_reactors:reactor_glass"},
        {pos: [6, 1, 6], state: "colossal_reactors:reactor_glass"},
        {pos: [6, 1, 7], state: "colossal_reactors:reactor_casing"},
        {pos: [6, 2, 1], state: "colossal_reactors:reactor_casing"},
        {pos: [6, 2, 2], state: "colossal_reactors:reactor_glass"},
        {pos: [6, 2, 3], state: "colossal_reactors:reactor_glass"},
        {pos: [6, 2, 4], state: "colossal_reactors:reactor_glass"},
        {pos: [6, 2, 5], state: "colossal_reactors:reactor_glass"},
        {pos: [6, 2, 6], state: "colossal_reactors:reactor_glass"},
        {pos: [6, 2, 7], state: "colossal_reactors:reactor_casing"},
        {pos: [6, 3, 1], state: "colossal_reactors:reactor_casing"},
        {pos: [6, 3, 2], state: "colossal_reactors:reactor_glass"},
        {pos: [6, 3, 3], state: "colossal_reactors:reactor_glass"},
        {pos: [6, 3, 4], state: "colossal_reactors:reactor_glass"},
        {pos: [6, 3, 5], state: "colossal_reactors:reactor_glass"},
        {pos: [6, 3, 6], state: "colossal_reactors:reactor_glass"},
        {pos: [6, 3, 7], state: "colossal_reactors:reactor_casing"},
        {pos: [6, 4, 1], state: "colossal_reactors:reactor_casing"},
        {pos: [6, 4, 2], state: "colossal_reactors:reactor_glass"},
        {pos: [6, 4, 3], state: "colossal_reactors:reactor_glass"},
        {pos: [6, 4, 4], state: "colossal_reactors:reactor_glass"},
        {pos: [6, 4, 5], state: "colossal_reactors:reactor_glass"},
        {pos: [6, 4, 6], state: "colossal_reactors:reactor_glass"},
        {pos: [6, 4, 7], state: "colossal_reactors:reactor_casing"},
        {pos: [6, 5, 1], state: "colossal_reactors:reactor_casing"},
        {pos: [6, 5, 2], state: "colossal_reactors:reactor_glass"},
        {pos: [6, 5, 3], state: "colossal_reactors:reactor_glass"},
        {pos: [6, 5, 4], state: "colossal_reactors:reactor_glass"},
        {pos: [6, 5, 5], state: "colossal_reactors:reactor_glass"},
        {pos: [6, 5, 6], state: "colossal_reactors:reactor_glass"},
        {pos: [6, 5, 7], state: "colossal_reactors:reactor_casing"},
        {pos: [6, 6, 1], state: "colossal_reactors:reactor_casing"},
        {pos: [6, 6, 2], state: "colossal_reactors:reactor_casing"},
        {pos: [6, 6, 3], state: "colossal_reactors:reactor_casing"},
        {pos: [6, 6, 4], state: "colossal_reactors:reactor_casing"},
        {pos: [6, 6, 5], state: "colossal_reactors:reactor_casing"},
        {pos: [6, 6, 6], state: "colossal_reactors:reactor_casing"},
        {pos: [6, 6, 7], state: "colossal_reactors:reactor_casing"}
    ],
    entities: [],
    palette: [
        "colossal_reactors:reactor_casing",
        "colossal_reactors:reactor_glass",
        "colossal_reactors:resource_port",
        "colossal_reactors:power_port",
        "colossal_reactors:reactor_rod{fill:0}",
        "colossal_reactors:reactor_controller{facing:north,state:off}",
        "colossal_reactors:rod_controller"
    ]
}
