{
    DataVersion: 3465,
    size: [7, 7, 8],
    data: [
        {pos: [3, 3, 0], state: "colossal_reactors:turbine_controller{facing:north,visual:off}"},
        {pos: [0, 0, 1], state: "colossal_reactors:turbine_casing"},
        {pos: [1, 0, 1], state: "colossal_reactors:turbine_casing"},
        {pos: [2, 0, 1], state: "colossal_reactors:turbine_casing"},
        {pos: [3, 0, 1], state: "colossal_reactors:turbine_casing"},
        {pos: [4, 0, 1], state: "colossal_reactors:turbine_casing"},
        {pos: [5, 0, 1], state: "colossal_reactors:turbine_casing"},
        {pos: [6, 0, 1], state: "colossal_reactors:turbine_casing"},
        {pos: [0, 1, 1], state: "colossal_reactors:turbine_casing"},
        {pos: [1, 1, 1], state: "colossal_reactors:turbine_glass"},
        {pos: [2, 1, 1], state: "colossal_reactors:turbine_glass"},
        {pos: [3, 1, 1], state: "colossal_reactors:turbine_glass"},
        {pos: [4, 1, 1], state: "colossal_reactors:turbine_glass"},
        {pos: [5, 1, 1], state: "colossal_reactors:turbine_glass"},
        {pos: [6, 1, 1], state: "colossal_reactors:turbine_casing"},
        {pos: [0, 2, 1], state: "colossal_reactors:turbine_casing"},
        {pos: [1, 2, 1], state: "colossal_reactors:turbine_resource_port"},
        {pos: [2, 2, 1], state: "colossal_reactors:turbine_glass"},
        {pos: [3, 2, 1], state: "colossal_reactors:turbine_power_port"},
        {pos: [4, 2, 1], state: "colossal_reactors:turbine_glass"},
        {pos: [5, 2, 1], state: "colossal_reactors:turbine_resource_port"},
        {pos: [6, 2, 1], state: "colossal_reactors:turbine_casing"},
        {pos: [0, 3, 1], state: "colossal_reactors:turbine_casing"},
        {pos: [1, 3, 1], state: "colossal_reactors:turbine_glass"},
        {pos: [2, 3, 1], state: "colossal_reactors:turbine_glass"},
        {pos: [3, 3, 1], state: "colossal_reactors:turbine_glass"},
        {pos: [4, 3, 1], state: "colossal_reactors:turbine_glass"},
        {pos: [5, 3, 1], state: "colossal_reactors:turbine_glass"},
        {pos: [6, 3, 1], state: "colossal_reactors:turbine_casing"},
        {pos: [0, 4, 1], state: "colossal_reactors:turbine_casing"},
        {pos: [1, 4, 1], state: "colossal_reactors:turbine_glass"},
        {pos: [2, 4, 1], state: "colossal_reactors:turbine_glass"},
        {pos: [3, 4, 1], state: "colossal_reactors:turbine_glass"},
        {pos: [4, 4, 1], state: "colossal_reactors:turbine_glass"},
        {pos: [5, 4, 1], state: "colossal_reactors:turbine_glass"},
        {pos: [6, 4, 1], state: "colossal_reactors:turbine_casing"},
        {pos: [0, 5, 1], state: "colossal_reactors:turbine_casing"},
        {pos: [1, 5, 1], state: "colossal_reactors:turbine_glass"},
        {pos: [2, 5, 1], state: "colossal_reactors:turbine_glass"},
        {pos: [3, 5, 1], state: "colossal_reactors:turbine_glass"},
        {pos: [4, 5, 1], state: "colossal_reactors:turbine_glass"},
        {pos: [5, 5, 1], state: "colossal_reactors:turbine_glass"},
        {pos: [6, 5, 1], state: "colossal_reactors:turbine_casing"},
        {pos: [0, 6, 1], state: "colossal_reactors:turbine_casing"},
        {pos: [1, 6, 1], state: "colossal_reactors:turbine_casing"},
        {pos: [2, 6, 1], state: "colossal_reactors:turbine_casing"},
        {pos: [3, 6, 1], state: "colossal_reactors:turbine_casing"},
        {pos: [4, 6, 1], state: "colossal_reactors:turbine_casing"},
        {pos: [5, 6, 1], state: "colossal_reactors:turbine_casing"},
        {pos: [6, 6, 1], state: "colossal_reactors:turbine_casing"},
        {pos: [0, 0, 2], state: "colossal_reactors:turbine_casing"},
        {pos: [1, 0, 2], state: "colossal_reactors:turbine_casing"},
        {pos: [2, 0, 2], state: "colossal_reactors:turbine_casing"},
        {pos: [3, 0, 2], state: "colossal_reactors:turbine_casing"},
        {pos: [4, 0, 2], state: "colossal_reactors:turbine_casing"},
        {pos: [5, 0, 2], state: "colossal_reactors:turbine_casing"},
        {pos: [6, 0, 2], state: "colossal_reactors:turbine_casing"},
        {pos: [0, 1, 2], state: "colossal_reactors:turbine_glass"},
        {pos: [6, 1, 2], state: "colossal_reactors:turbine_glass"},
        {pos: [0, 2, 2], state: "colossal_reactors:turbine_glass"},
        {pos: [3, 2, 2], state: "colossal_reactors:turbine_blade{facing:north}"},
        {pos: [6, 2, 2], state: "colossal_reactors:turbine_glass"},
        {pos: [0, 3, 2], state: "colossal_reactors:turbine_casing"},
        {pos: [1, 3, 2], state: "colossal_reactors:turbine_casing"},
        {pos: [2, 3, 2], state: "colossal_reactors:turbine_casing"},
        {pos: [3, 3, 2], state: "colossal_reactors:turbine_casing"},
        {pos: [4, 3, 2], state: "colossal_reactors:turbine_casing"},
        {pos: [5, 3, 2], state: "colossal_reactors:turbine_casing"},
        {pos: [6, 3, 2], state: "colossal_reactors:turbine_casing"},
        {pos: [0, 4, 2], state: "colossal_reactors:turbine_glass"},
        {pos: [1, 4, 2], state: "minecraft:copper_block"},
        {pos: [2, 4, 2], state: "minecraft:copper_block"},
        {pos: [3, 4, 2], state: "minecraft:copper_block"},
        {pos: [4, 4, 2], state: "minecraft:copper_block"},
        {pos: [5, 4, 2], state: "minecraft:copper_block"},
        {pos: [6, 4, 2], state: "colossal_reactors:turbine_glass"},
        {pos: [0, 5, 2], state: "colossal_reactors:turbine_glass"},
        {pos: [1, 5, 2], state: "minecraft:copper_block"},
        {pos: [2, 5, 2], state: "minecraft:copper_block"},
        {pos: [3, 5, 2], state: "minecraft:copper_block"},
        {pos: [4, 5, 2], state: "minecraft:copper_block"},
        {pos: [5, 5, 2], state: "minecraft:copper_block"},
        {pos: [6, 5, 2], state: "colossal_reactors:turbine_glass"},
        {pos: [0, 6, 2], state: "colossal_reactors:turbine_casing"},
        {pos: [1, 6, 2], state: "colossal_reactors:turbine_casing"},
        {pos: [2, 6, 2], state: "colossal_reactors:turbine_casing"},
        {pos: [3, 6, 2], state: "colossal_reactors:turbine_casing"},
        {pos: [4, 6, 2], state: "colossal_reactors:turbine_casing"},
        {pos: [5, 6, 2], state: "colossal_reactors:turbine_casing"},
        {pos: [6, 6, 2], state: "colossal_reactors:turbine_casing"},
        {pos: [0, 0, 3], state: "colossal_reactors:turbine_casing"},
        {pos: [1, 0, 3], state: "colossal_reactors:turbine_casing"},
        {pos: [2, 0, 3], state: "colossal_reactors:turbine_casing"},
        {pos: [3, 0, 3], state: "colossal_reactors:turbine_casing"},
        {pos: [4, 0, 3], state: "colossal_reactors:turbine_casing"},
        {pos: [5, 0, 3], state: "colossal_reactors:turbine_casing"},
        {pos: [6, 0, 3], state: "colossal_reactors:turbine_casing"},
        {pos: [0, 1, 3], state: "colossal_reactors:turbine_glass"},
        {pos: [3, 1, 3], state: "colossal_reactors:turbine_blade{facing:north}"},
        {pos: [6, 1, 3], state: "colossal_reactors:turbine_glass"},
        {pos: [0, 2, 3], state: "colossal_reactors:turbine_glass"},
        {pos: [3, 2, 3], state: "colossal_reactors:turbine_blade{facing:north}"},
        {pos: [6, 2, 3], state: "colossal_reactors:turbine_glass"},
        {pos: [0, 3, 3], state: "colossal_reactors:turbine_casing"},
        {pos: [1, 3, 3], state: "colossal_reactors:turbine_casing"},
        {pos: [2, 3, 3], state: "colossal_reactors:turbine_casing"},
        {pos: [3, 3, 3], state: "colossal_reactors:turbine_casing"},
        {pos: [4, 3, 3], state: "colossal_reactors:turbine_casing"},
        {pos: [5, 3, 3], state: "colossal_reactors:turbine_casing"},
        {pos: [6, 3, 3], state: "colossal_reactors:turbine_casing"},
        {pos: [0, 4, 3], state: "colossal_reactors:turbine_glass"},
        {pos: [1, 4, 3], state: "minecraft:copper_block"},
        {pos: [2, 4, 3], state: "minecraft:copper_block"},
        {pos: [3, 4, 3], state: "minecraft:copper_block"},
        {pos: [4, 4, 3], state: "minecraft:copper_block"},
        {pos: [5, 4, 3], state: "minecraft:copper_block"},
        {pos: [6, 4, 3], state: "colossal_reactors:turbine_glass"},
        {pos: [0, 5, 3], state: "colossal_reactors:turbine_glass"},
        {pos: [1, 5, 3], state: "minecraft:copper_block"},
        {pos: [2, 5, 3], state: "minecraft:copper_block"},
        {pos: [3, 5, 3], state: "minecraft:copper_block"},
        {pos: [4, 5, 3], state: "minecraft:copper_block"},
        {pos: [5, 5, 3], state: "minecraft:copper_block"},
        {pos: [6, 5, 3], state: "colossal_reactors:turbine_glass"},
        {pos: [0, 6, 3], state: "colossal_reactors:turbine_casing"},
        {pos: [1, 6, 3], state: "colossal_reactors:turbine_casing"},
        {pos: [2, 6, 3], state: "colossal_reactors:turbine_casing"},
        {pos: [3, 6, 3], state: "colossal_reactors:turbine_casing"},
        {pos: [4, 6, 3], state: "colossal_reactors:turbine_casing"},
        {pos: [5, 6, 3], state: "colossal_reactors:turbine_casing"},
        {pos: [6, 6, 3], state: "colossal_reactors:turbine_casing"},
        {pos: [0, 0, 4], state: "colossal_reactors:turbine_casing"},
        {pos: [1, 0, 4], state: "colossal_reactors:turbine_casing"},
        {pos: [2, 0, 4], state: "colossal_reactors:turbine_casing"},
        {pos: [3, 0, 4], state: "colossal_reactors:turbine_casing"},
        {pos: [4, 0, 4], state: "colossal_reactors:turbine_casing"},
        {pos: [5, 0, 4], state: "colossal_reactors:turbine_casing"},
        {pos: [6, 0, 4], state: "colossal_reactors:turbine_casing"},
        {pos: [0, 1, 4], state: "colossal_reactors:turbine_glass"},
        {pos: [2, 1, 4], state: "colossal_reactors:turbine_blade{facing:west}"},
        {pos: [3, 1, 4], state: "colossal_reactors:turbine_rod{facing:up}"},
        {pos: [4, 1, 4], state: "colossal_reactors:turbine_blade{facing:east}"},
        {pos: [6, 1, 4], state: "colossal_reactors:turbine_glass"},
        {pos: [0, 2, 4], state: "colossal_reactors:turbine_glass"},
        {pos: [1, 2, 4], state: "colossal_reactors:turbine_blade{facing:west}"},
        {pos: [2, 2, 4], state: "colossal_reactors:turbine_blade{facing:west}"},
        {pos: [3, 2, 4], state: "colossal_reactors:turbine_rod{facing:up}"},
        {pos: [4, 2, 4], state: "colossal_reactors:turbine_blade{facing:east}"},
        {pos: [5, 2, 4], state: "colossal_reactors:turbine_blade{facing:east}"},
        {pos: [6, 2, 4], state: "colossal_reactors:turbine_glass"},
        {pos: [0, 3, 4], state: "colossal_reactors:turbine_casing"},
        {pos: [1, 3, 4], state: "colossal_reactors:turbine_casing"},
        {pos: [2, 3, 4], state: "colossal_reactors:turbine_casing"},
        {pos: [3, 3, 4], state: "colossal_reactors:turbine_rod_controller"},
        {pos: [4, 3, 4], state: "colossal_reactors:turbine_casing"},
        {pos: [5, 3, 4], state: "colossal_reactors:turbine_casing"},
        {pos: [6, 3, 4], state: "colossal_reactors:turbine_casing"},
        {pos: [0, 4, 4], state: "colossal_reactors:turbine_glass"},
        {pos: [1, 4, 4], state: "minecraft:copper_block"},
        {pos: [2, 4, 4], state: "minecraft:copper_block"},
        {pos: [3, 4, 4], state: "minecraft:copper_block"},
        {pos: [4, 4, 4], state: "minecraft:copper_block"},
        {pos: [5, 4, 4], state: "minecraft:copper_block"},
        {pos: [6, 4, 4], state: "colossal_reactors:turbine_glass"},
        {pos: [0, 5, 4], state: "colossal_reactors:turbine_glass"},
        {pos: [1, 5, 4], state: "minecraft:copper_block"},
        {pos: [2, 5, 4], state: "minecraft:copper_block"},
        {pos: [3, 5, 4], state: "minecraft:copper_block"},
        {pos: [4, 5, 4], state: "minecraft:copper_block"},
        {pos: [5, 5, 4], state: "minecraft:copper_block"},
        {pos: [6, 5, 4], state: "colossal_reactors:turbine_glass"},
        {pos: [0, 6, 4], state: "colossal_reactors:turbine_casing"},
        {pos: [1, 6, 4], state: "colossal_reactors:turbine_casing"},
        {pos: [2, 6, 4], state: "colossal_reactors:turbine_casing"},
        {pos: [3, 6, 4], state: "colossal_reactors:turbine_casing"},
        {pos: [4, 6, 4], state: "colossal_reactors:turbine_casing"},
        {pos: [5, 6, 4], state: "colossal_reactors:turbine_casing"},
        {pos: [6, 6, 4], state: "colossal_reactors:turbine_casing"},
        {pos: [0, 0, 5], state: "colossal_reactors:turbine_casing"},
        {pos: [1, 0, 5], state: "colossal_reactors:turbine_casing"},
        {pos: [2, 0, 5], state: "colossal_reactors:turbine_casing"},
        {pos: [3, 0, 5], state: "colossal_reactors:turbine_casing"},
        {pos: [4, 0, 5], state: "colossal_reactors:turbine_casing"},
        {pos: [5, 0, 5], state: "colossal_reactors:turbine_casing"},
        {pos: [6, 0, 5], state: "colossal_reactors:turbine_casing"},
        {pos: [0, 1, 5], state: "colossal_reactors:turbine_glass"},
        {pos: [3, 1, 5], state: "colossal_reactors:turbine_blade{facing:south}"},
        {pos: [6, 1, 5], state: "colossal_reactors:turbine_glass"},
        {pos: [0, 2, 5], state: "colossal_reactors:turbine_glass"},
        {pos: [3, 2, 5], state: "colossal_reactors:turbine_blade{facing:south}"},
        {pos: [6, 2, 5], state: "colossal_reactors:turbine_glass"},
        {pos: [0, 3, 5], state: "colossal_reactors:turbine_casing"},
        {pos: [1, 3, 5], state: "colossal_reactors:turbine_casing"},
        {pos: [2, 3, 5], state: "colossal_reactors:turbine_casing"},
        {pos: [3, 3, 5], state: "colossal_reactors:turbine_casing"},
        {pos: [4, 3, 5], state: "colossal_reactors:turbine_casing"},
        {pos: [5, 3, 5], state: "colossal_reactors:turbine_casing"},
        {pos: [6, 3, 5], state: "colossal_reactors:turbine_casing"},
        {pos: [0, 4, 5], state: "colossal_reactors:turbine_glass"},
        {pos: [1, 4, 5], state: "minecraft:copper_block"},
        {pos: [2, 4, 5], state: "minecraft:copper_block"},
        {pos: [3, 4, 5], state: "minecraft:copper_block"},
        {pos: [4, 4, 5], state: "minecraft:copper_block"},
        {pos: [5, 4, 5], state: "minecraft:copper_block"},
        {pos: [6, 4, 5], state: "colossal_reactors:turbine_glass"},
        {pos: [0, 5, 5], state: "colossal_reactors:turbine_glass"},
        {pos: [1, 5, 5], state: "minecraft:copper_block"},
        {pos: [2, 5, 5], state: "minecraft:copper_block"},
        {pos: [3, 5, 5], state: "minecraft:copper_block"},
        {pos: [4, 5, 5], state: "minecraft:copper_block"},
        {pos: [5, 5, 5], state: "minecraft:copper_block"},
        {pos: [6, 5, 5], state: "colossal_reactors:turbine_glass"},
        {pos: [0, 6, 5], state: "colossal_reactors:turbine_casing"},
        {pos: [1, 6, 5], state: "colossal_reactors:turbine_casing"},
        {pos: [2, 6, 5], state: "colossal_reactors:turbine_casing"},
        {pos: [3, 6, 5], state: "colossal_reactors:turbine_casing"},
        {pos: [4, 6, 5], state: "colossal_reactors:turbine_casing"},
        {pos: [5, 6, 5], state: "colossal_reactors:turbine_casing"},
        {pos: [6, 6, 5], state: "colossal_reactors:turbine_casing"},
        {pos: [0, 0, 6], state: "colossal_reactors:turbine_casing"},
        {pos: [1, 0, 6], state: "colossal_reactors:turbine_casing"},
        {pos: [2, 0, 6], state: "colossal_reactors:turbine_casing"},
        {pos: [3, 0, 6], state: "colossal_reactors:turbine_casing"},
        {pos: [4, 0, 6], state: "colossal_reactors:turbine_casing"},
        {pos: [5, 0, 6], state: "colossal_reactors:turbine_casing"},
        {pos: [6, 0, 6], state: "colossal_reactors:turbine_casing"},
        {pos: [0, 1, 6], state: "colossal_reactors:turbine_glass"},
        {pos: [6, 1, 6], state: "colossal_reactors:turbine_glass"},
        {pos: [0, 2, 6], state: "colossal_reactors:turbine_glass"},
        {pos: [3, 2, 6], state: "colossal_reactors:turbine_blade{facing:south}"},
        {pos: [6, 2, 6], state: "colossal_reactors:turbine_glass"},
        {pos: [0, 3, 6], state: "colossal_reactors:turbine_casing"},
        {pos: [1, 3, 6], state: "colossal_reactors:turbine_casing"},
        {pos: [2, 3, 6], state: "colossal_reactors:turbine_casing"},
        {pos: [3, 3, 6], state: "colossal_reactors:turbine_casing"},
        {pos: [4, 3, 6], state: "colossal_reactors:turbine_casing"},
        {pos: [5, 3, 6], state: "colossal_reactors:turbine_casing"},
        {pos: [6, 3, 6], state: "colossal_reactors:turbine_casing"},
        {pos: [0, 4, 6], state: "colossal_reactors:turbine_glass"},
        {pos: [1, 4, 6], state: "minecraft:copper_block"},
        {pos: [2, 4, 6], state: "minecraft:copper_block"},
        {pos: [3, 4, 6], state: "minecraft:copper_block"},
        {pos: [4, 4, 6], state: "minecraft:copper_block"},
        {pos: [5, 4, 6], state: "minecraft:copper_block"},
        {pos: [6, 4, 6], state: "colossal_reactors:turbine_glass"},
        {pos: [0, 5, 6], state: "colossal_reactors:turbine_glass"},
        {pos: [1, 5, 6], state: "minecraft:copper_block"},
        {pos: [2, 5, 6], state: "minecraft:copper_block"},
        {pos: [3, 5, 6], state: "minecraft:copper_block"},
        {pos: [4, 5, 6], state: "minecraft:copper_block"},
        {pos: [5, 5, 6], state: "minecraft:copper_block"},
        {pos: [6, 5, 6], state: "colossal_reactors:turbine_glass"},
        {pos: [0, 6, 6], state: "colossal_reactors:turbine_casing"},
        {pos: [1, 6, 6], state: "colossal_reactors:turbine_casing"},
        {pos: [2, 6, 6], state: "colossal_reactors:turbine_casing"},
        {pos: [3, 6, 6], state: "colossal_reactors:turbine_casing"},
        {pos: [4, 6, 6], state: "colossal_reactors:turbine_casing"},
        {pos: [5, 6, 6], state: "colossal_reactors:turbine_casing"},
        {pos: [6, 6, 6], state: "colossal_reactors:turbine_casing"},
        {pos: [0, 0, 7], state: "colossal_reactors:turbine_casing"},
        {pos: [1, 0, 7], state: "colossal_reactors:turbine_casing"},
        {pos: [2, 0, 7], state: "colossal_reactors:turbine_casing"},
        {pos: [3, 0, 7], state: "colossal_reactors:turbine_casing"},
        {pos: [4, 0, 7], state: "colossal_reactors:turbine_casing"},
        {pos: [5, 0, 7], state: "colossal_reactors:turbine_casing"},
        {pos: [6, 0, 7], state: "colossal_reactors:turbine_casing"},
        {pos: [0, 1, 7], state: "colossal_reactors:turbine_casing"},
        {pos: [1, 1, 7], state: "colossal_reactors:turbine_glass"},
        {pos: [2, 1, 7], state: "colossal_reactors:turbine_glass"},
        {pos: [3, 1, 7], state: "colossal_reactors:turbine_glass"},
        {pos: [4, 1, 7], state: "colossal_reactors:turbine_glass"},
        {pos: [5, 1, 7], state: "colossal_reactors:turbine_glass"},
        {pos: [6, 1, 7], state: "colossal_reactors:turbine_casing"},
        {pos: [0, 2, 7], state: "colossal_reactors:turbine_casing"},
        {pos: [1, 2, 7], state: "colossal_reactors:turbine_glass"},
        {pos: [2, 2, 7], state: "colossal_reactors:turbine_glass"},
        {pos: [3, 2, 7], state: "colossal_reactors:turbine_glass"},
        {pos: [4, 2, 7], state: "colossal_reactors:turbine_glass"},
        {pos: [5, 2, 7], state: "colossal_reactors:turbine_glass"},
        {pos: [6, 2, 7], state: "colossal_reactors:turbine_casing"},
        {pos: [0, 3, 7], state: "colossal_reactors:turbine_casing"},
        {pos: [1, 3, 7], state: "colossal_reactors:turbine_casing"},
        {pos: [2, 3, 7], state: "colossal_reactors:turbine_casing"},
        {pos: [3, 3, 7], state: "colossal_reactors:turbine_casing"},
        {pos: [4, 3, 7], state: "colossal_reactors:turbine_casing"},
        {pos: [5, 3, 7], state: "colossal_reactors:turbine_casing"},
        {pos: [6, 3, 7], state: "colossal_reactors:turbine_casing"},
        {pos: [0, 4, 7], state: "colossal_reactors:turbine_casing"},
        {pos: [1, 4, 7], state: "colossal_reactors:turbine_glass"},
        {pos: [2, 4, 7], state: "colossal_reactors:turbine_glass"},
        {pos: [3, 4, 7], state: "colossal_reactors:turbine_glass"},
        {pos: [4, 4, 7], state: "colossal_reactors:turbine_glass"},
        {pos: [5, 4, 7], state: "colossal_reactors:turbine_glass"},
        {pos: [6, 4, 7], state: "colossal_reactors:turbine_casing"},
        {pos: [0, 5, 7], state: "colossal_reactors:turbine_casing"},
        {pos: [1, 5, 7], state: "colossal_reactors:turbine_glass"},
        {pos: [2, 5, 7], state: "colossal_reactors:turbine_glass"},
        {pos: [3, 5, 7], state: "colossal_reactors:turbine_glass"},
        {pos: [4, 5, 7], state: "colossal_reactors:turbine_glass"},
        {pos: [5, 5, 7], state: "colossal_reactors:turbine_glass"},
        {pos: [6, 5, 7], state: "colossal_reactors:turbine_casing"},
        {pos: [0, 6, 7], state: "colossal_reactors:turbine_casing"},
        {pos: [1, 6, 7], state: "colossal_reactors:turbine_casing"},
        {pos: [2, 6, 7], state: "colossal_reactors:turbine_casing"},
        {pos: [3, 6, 7], state: "colossal_reactors:turbine_casing"},
        {pos: [4, 6, 7], state: "colossal_reactors:turbine_casing"},
        {pos: [5, 6, 7], state: "colossal_reactors:turbine_casing"},
        {pos: [6, 6, 7], state: "colossal_reactors:turbine_casing"},
    ],
    entities: [],
    palette: [
        "colossal_reactors:turbine_blade{facing:east}",
        "colossal_reactors:turbine_blade{facing:north}",
        "colossal_reactors:turbine_blade{facing:south}",
        "colossal_reactors:turbine_blade{facing:west}",
        "colossal_reactors:turbine_casing",
        "colossal_reactors:turbine_controller{facing:north,visual:off}",
        "colossal_reactors:turbine_glass",
        "colossal_reactors:turbine_power_port",
        "colossal_reactors:turbine_resource_port",
        "colossal_reactors:turbine_rod{facing:up}",
        "colossal_reactors:turbine_rod_controller",
        "minecraft:copper_block",
    ]
}
